C:\Users\Clark\PycharmProjects\WeatherDataRecorder\venv\Scripts\python.exe C:/Users/Clark/PycharmProjects/WeatherDataRecorder/scraperDrJackMaps.py
Getting Map: http://www.drjack.info/BLIP/NAM/SE/FCST/wfpm_woustar.curr.18z.PNG
Traceback (most recent call last):
  File "C:\Users\Clark\PycharmProjects\WeatherDataRecorder\venv\lib\site-packages\urllib3\connection.py", line 160, in _new_conn
    (self._dns_host, self.port), self.timeout, **extra_kw
  File "C:\Users\Clark\PycharmProjects\WeatherDataRecorder\venv\lib\site-packages\urllib3\util\connection.py", line 84, in create_connection
    raise err
  File "C:\Users\Clark\PycharmProjects\WeatherDataRecorder\venv\lib\site-packages\urllib3\util\connection.py", line 74, in create_connection
    sock.connect(sa)
TimeoutError: [WinError 10060] A connection attempt failed because the connected party did not properly respond after a period of time, or established connection failed because connected host has failed to respond

During handling of the above exception, another exception occurred:

Traceback (most recent call last):
  File "C:\Users\Clark\PycharmProjects\WeatherDataRecorder\venv\lib\site-packages\urllib3\connectionpool.py", line 677, in urlopen
    chunked=chunked,
  File "C:\Users\Clark\PycharmProjects\WeatherDataRecorder\venv\lib\site-packages\urllib3\connectionpool.py", line 392, in _make_request
    conn.request(method, url, **httplib_request_kw)
  File "C:\Users\Clark\AppData\Local\Programs\Python\Python37\lib\http\client.py", line 1252, in request
    self._send_request(method, url, body, headers, encode_chunked)
  File "C:\Users\Clark\AppData\Local\Programs\Python\Python37\lib\http\client.py", line 1298, in _send_request
    self.endheaders(body, encode_chunked=encode_chunked)
  File "C:\Users\Clark\AppData\Local\Programs\Python\Python37\lib\http\client.py", line 1247, in endheaders
    self._send_output(message_body, encode_chunked=encode_chunked)
  File "C:\Users\Clark\AppData\Local\Programs\Python\Python37\lib\http\client.py", line 1026, in _send_output
    self.send(msg)
  File "C:\Users\Clark\AppData\Local\Programs\Python\Python37\lib\http\client.py", line 966, in send
    self.connect()
  File "C:\Users\Clark\PycharmProjects\WeatherDataRecorder\venv\lib\site-packages\urllib3\connection.py", line 187, in connect
    conn = self._new_conn()
  File "C:\Users\Clark\PycharmProjects\WeatherDataRecorder\venv\lib\site-packages\urllib3\connection.py", line 172, in _new_conn
    self, "Failed to establish a new connection: %s" % e
urllib3.exceptions.NewConnectionError: <urllib3.connection.HTTPConnection object at 0x000001FEFDAF0588>: Failed to establish a new connection: [WinError 10060] A connection attempt failed because the connected party did not properly respond after a period of time, or established connection failed because connected host has failed to respond

During handling of the above exception, another exception occurred:

Traceback (most recent call last):
  File "C:\Users\Clark\PycharmProjects\WeatherDataRecorder\venv\lib\site-packages\requests\adapters.py", line 449, in send
    timeout=timeout
  File "C:\Users\Clark\PycharmProjects\WeatherDataRecorder\venv\lib\site-packages\urllib3\connectionpool.py", line 725, in urlopen
    method, url, error=e, _pool=self, _stacktrace=sys.exc_info()[2]
  File "C:\Users\Clark\PycharmProjects\WeatherDataRecorder\venv\lib\site-packages\urllib3\util\retry.py", line 439, in increment
    raise MaxRetryError(_pool, url, error or ResponseError(cause))
urllib3.exceptions.MaxRetryError: HTTPConnectionPool(host='www.drjack.info', port=80): Max retries exceeded with url: /BLIP/NAM/SE/FCST/wfpm_woustar.curr.18z.PNG (Caused by NewConnectionError('<urllib3.connection.HTTPConnection object at 0x000001FEFDAF0588>: Failed to establish a new connection: [WinError 10060] A connection attempt failed because the connected party did not properly respond after a period of time, or established connection failed because connected host has failed to respond'))

During handling of the above exception, another exception occurred:

Traceback (most recent call last):
  File "C:/Users/Clark/PycharmProjects/WeatherDataRecorder/scraperDrJackMaps.py", line 178, in <module>
    schedule.run_pending()
  File "C:\Users\Clark\PycharmProjects\WeatherDataRecorder\venv\lib\site-packages\schedule\__init__.py", line 563, in run_pending
    default_scheduler.run_pending()
  File "C:\Users\Clark\PycharmProjects\WeatherDataRecorder\venv\lib\site-packages\schedule\__init__.py", line 94, in run_pending
    self._run_job(job)
  File "C:\Users\Clark\PycharmProjects\WeatherDataRecorder\venv\lib\site-packages\schedule\__init__.py", line 147, in _run_job
    ret = job.run()
  File "C:\Users\Clark\PycharmProjects\WeatherDataRecorder\venv\lib\site-packages\schedule\__init__.py", line 466, in run
    ret = self.job_func()
  File "C:/Users/Clark/PycharmProjects/WeatherDataRecorder/scraperDrJackMaps.py", line 139, in get_maps
    tempMap = session.get(maps_urls[i])
  File "C:\Users\Clark\PycharmProjects\WeatherDataRecorder\venv\lib\site-packages\requests\sessions.py", line 546, in get
    return self.request('GET', url, **kwargs)
  File "C:\Users\Clark\PycharmProjects\WeatherDataRecorder\venv\lib\site-packages\requests\sessions.py", line 533, in request
    resp = self.send(prep, **send_kwargs)
  File "C:\Users\Clark\PycharmProjects\WeatherDataRecorder\venv\lib\site-packages\requests\sessions.py", line 646, in send
    r = adapter.send(request, **kwargs)
  File "C:\Users\Clark\PycharmProjects\WeatherDataRecorder\venv\lib\site-packages\requests\adapters.py", line 516, in send
    raise ConnectionError(e, request=request)
requests.exceptions.ConnectionError: HTTPConnectionPool(host='www.drjack.info', port=80): Max retries exceeded with url: /BLIP/NAM/SE/FCST/wfpm_woustar.curr.18z.PNG (Caused by NewConnectionError('<urllib3.connection.HTTPConnection object at 0x000001FEFDAF0588>: Failed to establish a new connection: [WinError 10060] A connection attempt failed because the connected party did not properly respond after a period of time, or established connection failed because connected host has failed to respond'))

Process finished with exit code 1
